<?xml version='1.0' encoding='utf-8'?>
<robot name="env">

  <link name="background">
    <inertial>
      <origin xyz="0 0 0" rpy="0 0 0" />
      <mass value="0.1" />
      <inertia ixx="0.1" iyy="0.1" izz="0.1" ixy="0" ixz="0" iyz="0" />
    </inertial>
    <!-- <visual>
      <geometry>
        <mesh filename="../../../model/boxing_ring/meshes/boxingring.obj"/>
      </geometry>
    </visual> -->
  </link>

    <link name="ring">
      <inertial>
        <origin xyz="0 0 0" rpy="0 0 0" />
        <mass value="0.1" />
        <inertia ixx="0.1" iyy="0.1" izz="0.1" ixy="0" ixz="0" iyz="0" />
      </inertial>
      <visual>
        <geometry>
          <mesh filename="../../../model/boxing_ring/meshes/boxingring.obj"/>
        </geometry>
      </visual>
    </link>

    <link name="stand">
      <inertial>
        <origin xyz="0 0 0" rpy="0 0 0" />
        <mass value="0.1" />
        <inertia ixx="0.1" iyy="0.1" izz="0.1" ixy="0" ixz="0" iyz="0" />
      </inertial>
      <visual>
        <geometry>
          <mesh filename="../../../model/boxing_ring/meshes/stand.obj"/>
        </geometry>
      </visual>
    </link>

    <joint name="place_ring" type="revolute">
      <safety_controller k_position="100.0" k_velocity="40.0" soft_lower_limit="-2.8973" soft_upper_limit="2.8973"/>
      <origin rpy="1.57079632679 0 0" xyz="0.0 0.0 0.0"/>
      <parent link="background"/>
      <child link="ring"/>
      <axis xyz="0 0 1"/>
      <calibration falling="-80.0" />
      <limit effort="87" lower="-2.8973" upper="2.8973" velocity="2.1750"/>
    </joint>

    <joint name="place_stand" type="revolute">
      <safety_controller k_position="100.0" k_velocity="40.0" soft_lower_limit="-2.8973" soft_upper_limit="2.8973"/>
      <origin rpy="0 -1.57079632679 0" xyz="0.75 0.745 0" />
      <parent link="ring"/>
      <child link="stand"/>
      <axis xyz="0 0 1"/>
      <calibration falling="-80.0" />
      <limit effort="87" lower="-2.8973" upper="2.8973" velocity="2.1750"/>
    </joint>

</robot>
