<?xml version='1.0' encoding='utf-8'?>
<robot name="env">

  <link name="background">
    <inertial>
      <origin xyz="0 0 0" rpy="0 0 0" />
      <mass value="0.1" />
      <inertia ixx="0.1" iyy="0.1" izz="0.1" ixy="0" ixz="0" iyz="0" />
    </inertial>
    <!-- <visual>
      <geometry>
        <mesh filename="../../../model/boxing_ring/meshes/boxingring.obj"/>
      </geometry>
    </visual> -->
  </link>

    <link name="ring">
      <inertial>
        <origin xyz="0 0 0" rpy="0 0 0" />
        <mass value="0.1" />
        <inertia ixx="0.1" iyy="0.1" izz="0.1" ixy="0" ixz="0" iyz="0" />
      </inertial>
      <visual>
        <origin xyz="0 0 0" rpy="0 0 0" />
        <geometry>
          <mesh filename="../../../model/boxing_ring/meshes/boxingring.obj"/>
        </geometry>
      </visual>
    </link>

    <link name="stand">
      <inertial>
        <origin xyz="0 0 0" rpy="0 0 0" />
        <mass value="0.1" />
        <inertia ixx="0.1" iyy="0.1" izz="0.1" ixy="0" ixz="0" iyz="0" />
      </inertial>
      <visual>
        <origin xyz="0 0 0" rpy="0 0 0" />
        <geometry>
          <mesh filename="../../../model/boxing_ring/meshes/stand.obj"/>
        </geometry>
      </visual>
    </link>

    <joint name="place_ring" type="revolute">
      <safety_controller k_position="100.0" k_velocity="50.0" soft_lower_limit="-1.57079632679" soft_upper_limit="1.57079632679"/>
      <origin rpy="1.57079632679 0 0" xyz="0 0 0"/>
      <parent link="background"/>
      <child link="ring"/>
      <axis xyz="0 0 1"/>
      <limit effort="100" lower="-3.14159265359" upper="3.14159265359" velocity="3.14159265359"/>
    </joint>

    <joint name="place_stand" type="revolute">
      <safety_controller k_position="100.0" k_velocity="50.0" soft_lower_limit="-1.57079632679" soft_upper_limit="1.57079632679"/>
      <origin rpy="0 -1.57079632679 0" xyz="0 0 0" />
      <parent link="ring"/>
      <child link="stand"/>
      <axis xyz="0 0 1"/>
      <limit effort="100" lower="-3.14159265359" upper="3.14159265359" velocity="3.14159265359"/>
    </joint>

</robot>
