<?xml version='1.0' encoding='utf-8'?>
<robot name="punching_bag">

    <link name="link0">
      <inertial>
        <origin xyz="0 0 0" rpy="0 0 0" />
        <mass value="0.1" />
        <inertia ixx="0.1" iyy="0.1" izz="0.1" ixy="0" ixz="0" iyz="0" />
      </inertial>
      <!-- <visual>
        <geometry>
          <mesh filename="../../../model/boxing_ring/meshes/.../">
        </geometry>
      </visual> -->
<!--       <collision>
        <geometry>
          <mesh filename="../../../model/boxing_ring/meshes/.obj"/>
        </geometry>
      </collision> -->
    </link>
    <link name="link1">
      <inertial>
        <origin xyz="0 0 0" rpy="0 0 0" />
        <mass value="0.1" />
        <inertia ixx="0.1" iyy="0.1" izz="0.1" ixy="0" ixz="0" iyz="0" />
      </inertial>
      <!-- <visual>
        <geometry>
          <mesh filename="../../../model/boxing_ring/meshes/.obj"/>
        </geometry>
      </visual> -->
      <!-- <collision>
        <geometry>
          <mesh filename="../../../model/boxing_ring/meshes/.obj"/>
        </geometry>
      </collision> -->
    </link>
    <link name="link2">
      <inertial>
        <origin xyz="0 0 0" rpy="0 0 0" />
        <mass value="3" />
        <inertia ixx="0.3" iyy="0.3" izz="0.3" ixy="0" ixz="0" iyz="0" />
      </inertial>
      <!-- <visual>
        <geometry>
          <mesh filename="../../../model/boxing_ring/meshes/.obj"/>
        </geometry>
      </visual> -->
      <!-- <collision>
        <geometry>
          <mesh filename="../../../model/boxing_ring/meshes/.obj"/>
        </geometry>
      </collision> -->
    </link>
    <link name="bag">
      <inertial>
        <origin xyz="1.5 0 0" rpy="0 0 0" />
        <mass value="20" />
        <inertia ixx="0.2" iyy="0.2" izz="0.2" ixy="0" ixz="0" iyz="0" />
      </inertial>
      <visual>
        <geometry>
          <mesh filename="../../../model/boxing_ring/meshes/punchbag_blender.obj"/>
        </geometry>
      </visual>
      <!-- <collision>
        <geometry>
          <mesh filename="../../../model/panda/meshes/collision/link3.obj"/>
        </geometry>
      </collision> -->
    </link>

    <joint name="joint1" type="revolute">
      <safety_controller k_position="100.0" k_velocity="40.0" soft_lower_limit="-2.8973" soft_upper_limit="2.8973"/>
      <origin rpy="1.57079632679 0 0" xyz="0.75 0 0.9"/>
      <parent link="link0"/>
      <child link="link1"/>
      <axis xyz="0 0 1"/>
      <calibration falling="-80.0" />
      <limit effort="87" lower="-2.8973" upper="2.8973" velocity="2.1750"/>
    </joint>
    <joint name="joint2" type="revolute">
      <safety_controller k_position="100.0" k_velocity="40.0" soft_lower_limit="-1.7628" soft_upper_limit="1.7628"/>
      <origin rpy="0 0 0" xyz="0 0 0"/>
      <parent link="link1"/>
      <child link="link2"/>
      <axis xyz="0 0 1"/>
      <calibration falling="-45.0" />
      <limit effort="87" lower="-1.7628" upper="1.7628" velocity="2.1750"/>
    </joint>
    <joint name="joint3" type="revolute">
      <safety_controller k_position="100.0" k_velocity="40.0" soft_lower_limit="-2.8973" soft_upper_limit="2.8973"/>
      <origin rpy="0 0 0" xyz="0 0 0"/>
      <parent link="link2"/>
      <child link="bag"/>
      <axis xyz="0 0 1"/>
      <limit effort="87" lower="-2.8973" upper="2.8973" velocity="2.1750"/>
    </joint>

</robot>
